QXcbConnection: Could not connect to display 
Aborted
libEGL warning: DRI2: failed to authenticate
QXcbConnection: Could not connect to display 
Aborted
libEGL warning: DRI2: failed to authenticate
QXcbConnection: Could not connect to display 
Aborted
libEGL warning: DRI2: failed to authenticate
Traceback (most recent call last):
  File "main.py", line 9, in <module>
    ex = MainWindow()
  File "/home/pi/dash/Dashboard/test1/MainWindow.py", line 306, in __init__
    self.bus = can.interface.Bus(bustype='socketcan', channel='can0', bitrate=500000)
  File "/home/pi/.local/lib/python2.7/site-packages/can/interface.py", line 87, in __new__
    return cls(channel, **kwargs)
  File "/home/pi/.local/lib/python2.7/site-packages/can/interfaces/socketcan/socketcan_ctypes.py", line 62, in __init__
    error = bindSocket(self.socket, channel)
  File "/home/pi/.local/lib/python2.7/site-packages/can/interfaces/socketcan/socketcan_ctypes.py", line 276, in bindSocket
    raise can.CanError(m)
can.CanError: Failure while getting "can0" interface index.
libEGL warning: DRI2: failed to authenticate
Traceback (most recent call last):
  File "main.py", line 9, in <module>
    ex = MainWindow()
  File "/home/pi/dash/Dashboard/test1/MainWindow.py", line 306, in __init__
    self.bus = can.interface.Bus(bustype='socketcan', channel='can0', bitrate=500000)
  File "/home/pi/.local/lib/python2.7/site-packages/can/interface.py", line 87, in __new__
    return cls(channel, **kwargs)
  File "/home/pi/.local/lib/python2.7/site-packages/can/interfaces/socketcan/socketcan_ctypes.py", line 62, in __init__
    error = bindSocket(self.socket, channel)
  File "/home/pi/.local/lib/python2.7/site-packages/can/interfaces/socketcan/socketcan_ctypes.py", line 276, in bindSocket
    raise can.CanError(m)
can.CanError: Failure while getting "can0" interface index.
libEGL warning: DRI2: failed to authenticate
Traceback (most recent call last):
  File "main.py", line 9, in <module>
    ex = MainWindow()
  File "/home/pi/dash/Dashboard/test1/MainWindow.py", line 306, in __init__
    self.bus = can.interface.Bus(bustype='socketcan', channel='can0', bitrate=500000)
  File "/home/pi/.local/lib/python2.7/site-packages/can/interface.py", line 87, in __new__
    return cls(channel, **kwargs)
  File "/home/pi/.local/lib/python2.7/site-packages/can/interfaces/socketcan/socketcan_ctypes.py", line 62, in __init__
    error = bindSocket(self.socket, channel)
  File "/home/pi/.local/lib/python2.7/site-packages/can/interfaces/socketcan/socketcan_ctypes.py", line 276, in bindSocket
    raise can.CanError(m)
can.CanError: Failure while getting "can0" interface index.
QXcbConnection: Could not connect to display 
Aborted
libEGL warning: DRI2: failed to authenticate
QXcbConnection: Could not connect to display 
Aborted
libEGL warning: DRI2: failed to authenticate
QCoreApplication::exec: The event loop is already running
Traceback (most recent call last):
  File "main.py", line 4, in <module>
    from MainWindow import MainWindow
  File "/home/pi/dash/Dashboard/test1/MainWindow.py", line 26, in <module>
    bytesize=serial.SEVENBITS
  File "/home/pi/dash/Dashboard/test1/serial/serialutil.py", line 240, in __init__
    self.open()
  File "/home/pi/dash/Dashboard/test1/serial/serialposix.py", line 268, in open
    raise SerialException(msg.errno, "could not open port {}: {}".format(self._port, msg))
serial.serialutil.SerialException: [Errno 2] could not open port /dev/ttyACM0: [Errno 2] No such file or directory: '/dev/ttyACM0'
Traceback (most recent call last):
  File "main.py", line 4, in <module>
    from MainWindow import MainWindow
  File "/home/pi/dash/Dashboard/test1/MainWindow.py", line 26, in <module>
    bytesize=serial.SEVENBITS
  File "/home/pi/dash/Dashboard/test1/serial/serialutil.py", line 240, in __init__
    self.open()
  File "/home/pi/dash/Dashboard/test1/serial/serialposix.py", line 268, in open
    raise SerialException(msg.errno, "could not open port {}: {}".format(self._port, msg))
serial.serialutil.SerialException: [Errno 2] could not open port /dev/ttyACM0: [Errno 2] No such file or directory: '/dev/ttyACM0'
libEGL warning: DRI2: failed to authenticate
Traceback (most recent call last):
  File "main.py", line 4, in <module>
    from MainWindow import MainWindow
  File "/home/pi/dash/Dashboard/test1/MainWindow.py", line 549
    self.bus.flush_tx_buffer()
    ^
IndentationError: unexpected indent
Traceback (most recent call last):
  File "main.py", line 4, in <module>
    from MainWindow import MainWindow
  File "/home/pi/dash/Dashboard/test1/MainWindow.py", line 549
    self.bus.flush_tx_buffer()
    ^
IndentationError: unexpected indent
Traceback (most recent call last):
  File "main.py", line 4, in <module>
    from MainWindow import MainWindow
  File "/home/pi/dash/Dashboard/test1/MainWindow.py", line 549
    self.bus.flush_tx_buffer()
    ^
IndentationError: unexpected indent
Traceback (most recent call last):
  File "main.py", line 4, in <module>
    from MainWindow import MainWindow
  File "/home/pi/dash/Dashboard/test1/MainWindow.py", line 549
    self.bus.flush_tx_buffer()
    ^
IndentationError: unexpected indent
Traceback (most recent call last):
  File "main.py", line 4, in <module>
    from MainWindow import MainWindow
  File "/home/pi/dash/Dashboard/test1/MainWindow.py", line 550
    self.bus.flush_tx_buffer()
    ^
IndentationError: unexpected indent
Traceback (most recent call last):
  File "main.py", line 4, in <module>
    from MainWindow import MainWindow
  File "/home/pi/dash/Dashboard/test1/MainWindow.py", line 309
    printf("start")
    ^
IndentationError: unexpected indent
QXcbConnection: Could not connect to display 
Aborted
libEGL warning: DRI2: failed to authenticate
Traceback (most recent call last):
  File "main.py", line 9, in <module>
    ex = MainWindow()
  File "/home/pi/dash/Dashboard/test1/MainWindow.py", line 307, in __init__
    self.bus = can.interface.Bus(bustype='socketcan', channel='can0', bitrate=500000)
  File "/home/pi/.local/lib/python2.7/site-packages/can/interface.py", line 87, in __new__
    return cls(channel, **kwargs)
  File "/home/pi/.local/lib/python2.7/site-packages/can/interfaces/socketcan/socketcan_ctypes.py", line 62, in __init__
    error = bindSocket(self.socket, channel)
  File "/home/pi/.local/lib/python2.7/site-packages/can/interfaces/socketcan/socketcan_ctypes.py", line 276, in bindSocket
    raise can.CanError(m)
can.CanError: Failure while getting "can0" interface index.
libEGL warning: DRI2: failed to authenticate
Traceback (most recent call last):
  File "main.py", line 9, in <module>
    ex = MainWindow()
  File "/home/pi/dash/Dashboard/test1/MainWindow.py", line 307, in __init__
    self.bus = can.interface.Bus(bustype='socketcan', channel='can0', bitrate=500000)
  File "/home/pi/.local/lib/python2.7/site-packages/can/interface.py", line 87, in __new__
    return cls(channel, **kwargs)
  File "/home/pi/.local/lib/python2.7/site-packages/can/interfaces/socketcan/socketcan_ctypes.py", line 62, in __init__
    error = bindSocket(self.socket, channel)
  File "/home/pi/.local/lib/python2.7/site-packages/can/interfaces/socketcan/socketcan_ctypes.py", line 276, in bindSocket
    raise can.CanError(m)
can.CanError: Failure while getting "can0" interface index.
QXcbConnection: Could not connect to display 
Aborted
libEGL warning: DRI2: failed to authenticate
Traceback (most recent call last):
  File "main.py", line 9, in <module>
    ex = MainWindow()
  File "/home/pi/dash/Dashboard/test1/MainWindow.py", line 307, in __init__
    self.bus = can.interface.Bus(bustype='socketcan', channel='can0', bitrate=500000)
  File "/home/pi/.local/lib/python2.7/site-packages/can/interface.py", line 87, in __new__
    return cls(channel, **kwargs)
  File "/home/pi/.local/lib/python2.7/site-packages/can/interfaces/socketcan/socketcan_ctypes.py", line 62, in __init__
    error = bindSocket(self.socket, channel)
  File "/home/pi/.local/lib/python2.7/site-packages/can/interfaces/socketcan/socketcan_ctypes.py", line 276, in bindSocket
    raise can.CanError(m)
can.CanError: Failure while getting "can0" interface index.
QXcbConnection: Could not connect to display 
Aborted
libEGL warning: DRI2: failed to authenticate
Traceback (most recent call last):
  File "main.py", line 9, in <module>
    ex = MainWindow()
  File "/home/pi/dash/Dashboard/test1/MainWindow.py", line 307, in __init__
    self.bus = can.interface.Bus(bustype='socketcan', channel='can0', bitrate=500000)
  File "/home/pi/.local/lib/python2.7/site-packages/can/interface.py", line 87, in __new__
    return cls(channel, **kwargs)
  File "/home/pi/.local/lib/python2.7/site-packages/can/interfaces/socketcan/socketcan_ctypes.py", line 62, in __init__
    error = bindSocket(self.socket, channel)
  File "/home/pi/.local/lib/python2.7/site-packages/can/interfaces/socketcan/socketcan_ctypes.py", line 276, in bindSocket
    raise can.CanError(m)
can.CanError: Failure while getting "can0" interface index.
QXcbConnection: Could not connect to display 
Aborted
libEGL warning: DRI2: failed to authenticate
libEGL warning: DRI2: failed to authenticate
QXcbConnection: Could not connect to display 
Aborted
libEGL warning: DRI2: failed to authenticate
Traceback (most recent call last):
  File "/home/pi/dash/Dashboard/test1/MainWindow.py", line 478, in increment
    self.fastRead()
  File "/home/pi/dash/Dashboard/test1/MainWindow.py", line 398, in fastRead
    line = self.can_read(0x300)
  File "/home/pi/dash/Dashboard/test1/MainWindow.py", line 562, in can_read
    data = str(newMess)
NameError: global name 'newMess' is not defined
Aborted
libEGL warning: DRI2: failed to authenticate
Traceback (most recent call last):
  File "/home/pi/dash/Dashboard/test1/MainWindow.py", line 478, in increment
    self.fastRead()
  File "/home/pi/dash/Dashboard/test1/MainWindow.py", line 398, in fastRead
    line = self.can_read(0x300)
  File "/home/pi/dash/Dashboard/test1/MainWindow.py", line 562, in can_read
    data = str(newMess)
NameError: global name 'newMess' is not defined
Aborted
libEGL warning: DRI2: failed to authenticate
Traceback (most recent call last):
  File "/home/pi/dash/Dashboard/test1/MainWindow.py", line 478, in increment
    self.fastRead()
  File "/home/pi/dash/Dashboard/test1/MainWindow.py", line 398, in fastRead
    line = self.can_read(0x300)
  File "/home/pi/dash/Dashboard/test1/MainWindow.py", line 562, in can_read
    data = str(newMess)
NameError: global name 'newMess' is not defined
Aborted
libEGL warning: DRI2: failed to authenticate
Traceback (most recent call last):
  File "/home/pi/dash/Dashboard/test1/MainWindow.py", line 478, in increment
    self.fastRead()
  File "/home/pi/dash/Dashboard/test1/MainWindow.py", line 398, in fastRead
    line = self.can_read(0x300)
  File "/home/pi/dash/Dashboard/test1/MainWindow.py", line 562, in can_read
    data = str(newMess)
NameError: global name 'newMess' is not defined
Aborted
libEGL warning: DRI2: failed to authenticate
Traceback (most recent call last):
  File "/home/pi/dash/Dashboard/test1/MainWindow.py", line 478, in increment
    self.fastRead()
  File "/home/pi/dash/Dashboard/test1/MainWindow.py", line 398, in fastRead
    line = self.can_read(0x300)
  File "/home/pi/dash/Dashboard/test1/MainWindow.py", line 562, in can_read
    data = str(newMess)
NameError: global name 'newMess' is not defined
Aborted
libEGL warning: DRI2: failed to authenticate
Traceback (most recent call last):
  File "/home/pi/dash/Dashboard/test1/MainWindow.py", line 478, in increment
    self.fastRead()
  File "/home/pi/dash/Dashboard/test1/MainWindow.py", line 398, in fastRead
    line = self.can_read(0x300)
  File "/home/pi/dash/Dashboard/test1/MainWindow.py", line 562, in can_read
    data = str(newMess)
NameError: global name 'newMess' is not defined
Aborted
QXcbConnection: Could not connect to display 
Aborted
libEGL warning: DRI2: failed to authenticate
Traceback (most recent call last):
  File "/home/pi/dash/Dashboard/test1/MainWindow.py", line 478, in increment
    self.fastRead()
  File "/home/pi/dash/Dashboard/test1/MainWindow.py", line 398, in fastRead
    line = self.can_read(0x300)
  File "/home/pi/dash/Dashboard/test1/MainWindow.py", line 562, in can_read
    data = str(newMess)
NameError: global name 'newMess' is not defined
Aborted
libEGL warning: DRI2: failed to authenticate
Traceback (most recent call last):
  File "/home/pi/dash/Dashboard/test1/MainWindow.py", line 478, in increment
    self.fastRead()
  File "/home/pi/dash/Dashboard/test1/MainWindow.py", line 398, in fastRead
    line = self.can_read(0x300)
  File "/home/pi/dash/Dashboard/test1/MainWindow.py", line 562, in can_read
    data = str(newMess)
NameError: global name 'newMess' is not defined
Aborted
libEGL warning: DRI2: failed to authenticate
Traceback (most recent call last):
  File "/home/pi/dash/Dashboard/test1/MainWindow.py", line 478, in increment
    self.fastRead()
  File "/home/pi/dash/Dashboard/test1/MainWindow.py", line 398, in fastRead
    line = self.can_read(0x300)
  File "/home/pi/dash/Dashboard/test1/MainWindow.py", line 562, in can_read
    data = str(newMess)
NameError: global name 'newMess' is not defined
Aborted
libEGL warning: DRI2: failed to authenticate
Traceback (most recent call last):
  File "/home/pi/dash/Dashboard/test1/MainWindow.py", line 478, in increment
    self.fastRead()
  File "/home/pi/dash/Dashboard/test1/MainWindow.py", line 398, in fastRead
    line = self.can_read(0x300)
  File "/home/pi/dash/Dashboard/test1/MainWindow.py", line 562, in can_read
    data = str(newMess)
NameError: global name 'newMess' is not defined
Aborted
libEGL warning: DRI2: failed to authenticate
Traceback (most recent call last):
  File "/home/pi/dash/Dashboard/test1/MainWindow.py", line 478, in increment
    self.fastRead()
  File "/home/pi/dash/Dashboard/test1/MainWindow.py", line 398, in fastRead
    line = self.can_read(0x300)
  File "/home/pi/dash/Dashboard/test1/MainWindow.py", line 562, in can_read
    data = str(newMess)
NameError: global name 'newMess' is not defined
Aborted
libEGL warning: DRI2: failed to authenticate
Traceback (most recent call last):
  File "/home/pi/dash/Dashboard/test1/MainWindow.py", line 478, in increment
    self.fastRead()
  File "/home/pi/dash/Dashboard/test1/MainWindow.py", line 398, in fastRead
    line = self.can_read(0x300)
  File "/home/pi/dash/Dashboard/test1/MainWindow.py", line 562, in can_read
    data = str(newMess)
NameError: global name 'newMess' is not defined
Aborted
libEGL warning: DRI2: failed to authenticate
Traceback (most recent call last):
  File "/home/pi/dash/Dashboard/test1/MainWindow.py", line 478, in increment
    self.fastRead()
  File "/home/pi/dash/Dashboard/test1/MainWindow.py", line 398, in fastRead
    line = self.can_read(0x300)
  File "/home/pi/dash/Dashboard/test1/MainWindow.py", line 562, in can_read
    data = str(newMess)
NameError: global name 'newMess' is not defined
QXcbConnection: Could not connect to display 
Aborted
libEGL warning: DRI2: failed to authenticate
Traceback (most recent call last):
  File "main.py", line 9, in <module>
    ex = MainWindow()
  File "/home/pi/dash/Dashboard/test1/MainWindow.py", line 307, in __init__
    self.bus = can.interface.Bus(bustype='socketcan', channel='can0', bitrate=500000)
  File "/home/pi/.local/lib/python2.7/site-packages/can/interface.py", line 87, in __new__
    return cls(channel, **kwargs)
  File "/home/pi/.local/lib/python2.7/site-packages/can/interfaces/socketcan/socketcan_ctypes.py", line 62, in __init__
    error = bindSocket(self.socket, channel)
  File "/home/pi/.local/lib/python2.7/site-packages/can/interfaces/socketcan/socketcan_ctypes.py", line 276, in bindSocket
    raise can.CanError(m)
can.CanError: Failure while getting "can0" interface index.
                                                                                                                                                                                                                                                                                                                                                                                                                                                                                                                                             QXcbConnection: Could not connect to display 
Aborted
libEGL warning: DRI2: failed to authenticate
Traceback (most recent call last):
  File "/home/pi/dash/Dashboard/test1/MainWindow.py", line 478, in increment
    self.fastRead()
  File "/home/pi/dash/Dashboard/test1/MainWindow.py", line 398, in fastRead
    line = self.can_read(0x300)
  File "/home/pi/dash/Dashboard/test1/MainWindow.py", line 562, in can_read
    data = str(newMess)
NameError: global name 'newMess' is not defined
Aborted
libEGL warning: DRI2: failed to authenticate
Traceback (most recent call last):
  File "/home/pi/dash/Dashboard/test1/MainWindow.py", line 478, in increment
    self.fastRead()
  File "/home/pi/dash/Dashboard/test1/MainWindow.py", line 398, in fastRead
    line = self.can_read(0x300)
  File "/home/pi/dash/Dashboard/test1/MainWindow.py", line 562, in can_read
    data = str(newMess)
NameError: global name 'newMess' is not defined
Aborted
libEGL warning: DRI2: failed to authenticate
Traceback (most recent call last):
  File "/home/pi/dash/Dashboard/test1/MainWindow.py", line 478, in increment
    self.fastRead()
  File "/home/pi/dash/Dashboard/test1/MainWindow.py", line 398, in fastRead
    line = self.can_read(0x300)
  File "/home/pi/dash/Dashboard/test1/MainWindow.py", line 562, in can_read
    data = str(newMess)
NameError: global name 'newMess' is not defined
Aborted
libEGL warning: DRI2: failed to authenticate
Traceback (most recent call last):
  File "/home/pi/dash/Dashboard/test1/MainWindow.py", line 478, in increment
    self.fastRead()
  File "/home/pi/dash/Dashboard/test1/MainWindow.py", line 398, in fastRead
    line = self.can_read(0x300)
  File "/home/pi/dash/Dashboard/test1/MainWindow.py", line 562, in can_read
    data = str(newMess)
NameError: global name 'newMess' is not defined
Aborted
libEGL warning: DRI2: failed to authenticate
Traceback (most recent call last):
  File "/home/pi/dash/Dashboard/test1/MainWindow.py", line 478, in increment
    self.fastRead()
  File "/home/pi/dash/Dashboard/test1/MainWindow.py", line 398, in fastRead
    line = self.can_read(0x300)
  File "/home/pi/dash/Dashboard/test1/MainWindow.py", line 562, in can_read
    data = str(newMess)
NameError: global name 'newMess' is not defined
Aborted
libEGL warning: DRI2: failed to authenticate
Traceback (most recent call last):
  File "/home/pi/dash/Dashboard/test1/MainWindow.py", line 478, in increment
    self.fastRead()
  File "/home/pi/dash/Dashboard/test1/MainWindow.py", line 398, in fastRead
    line = self.can_read(0x300)
  File "/home/pi/dash/Dashboard/test1/MainWindow.py", line 562, in can_read
    data = str(newMess)
NameError: global name 'newMess' is not defined
Aborted
                                                                                                                                                                                                                                                                                                                                                                                                                                                                                                                                                                                                                                                                                                                                                                                                                                                                                                                                                                                                                                                                                                                                                                                                                                                                                                                                                                                                                                 QXcbConnection: Could not connect to display 
Aborted
libEGL warning: DRI2: failed to authenticate
Traceback (most recent call last):
  File "main.py", line 9, in <module>
    ex = MainWindow()
  File "/home/pi/dash/Dashboard/test1/MainWindow.py", line 307, in __init__
    self.bus = can.interface.Bus(bustype='socketcan', channel='can0', bitrate=500000)
  File "/home/pi/.local/lib/python2.7/site-packages/can/interface.py", line 87, in __new__
    return cls(channel, **kwargs)
  File "/home/pi/.local/lib/python2.7/site-packages/can/interfaces/socketcan/socketcan_ctypes.py", line 62, in __init__
    error = bindSocket(self.socket, channel)
  File "/home/pi/.local/lib/python2.7/site-packages/can/interfaces/socketcan/socketcan_ctypes.py", line 276, in bindSocket
    raise can.CanError(m)
can.CanError: Failure while getting "can0" interface index.
QXcbConnection: Could not connect to display 
Aborted
libEGL warning: DRI2: failed to authenticate
Traceback (most recent call last):
  File "main.py", line 9, in <module>
    ex = MainWindow()
  File "/home/pi/dash/Dashboard/test1/MainWindow.py", line 307, in __init__
    self.bus = can.interface.Bus(bustype='socketcan', channel='can0', bitrate=500000)
  File "/home/pi/.local/lib/python2.7/site-packages/can/interface.py", line 87, in __new__
    return cls(channel, **kwargs)
  File "/home/pi/.local/lib/python2.7/site-packages/can/interfaces/socketcan/socketcan_ctypes.py", line 62, in __init__
    error = bindSocket(self.socket, channel)
  File "/home/pi/.local/lib/python2.7/site-packages/can/interfaces/socketcan/socketcan_ctypes.py", line 276, in bindSocket
    raise can.CanError(m)
can.CanError: Failure while getting "can0" interface index.
QXcbConnection: Could not connect to display 
Aborted
libEGL warning: DRI2: failed to authenticate
Traceback (most recent call last):
  File "/home/pi/dash/Dashboard/test1/MainWindow.py", line 478, in increment
    self.fastRead()
  File "/home/pi/dash/Dashboard/test1/MainWindow.py", line 398, in fastRead
    line = self.can_read(0x300)
  File "/home/pi/dash/Dashboard/test1/MainWindow.py", line 562, in can_read
    data = str(newMess)
NameError: global name 'newMess' is not defined
Aborted
libEGL warning: DRI2: failed to authenticate
Traceback (most recent call last):
  File "/home/pi/dash/Dashboard/test1/MainWindow.py", line 478, in increment
    self.fastRead()
  File "/home/pi/dash/Dashboard/test1/MainWindow.py", line 398, in fastRead
    line = self.can_read(0x300)
  File "/home/pi/dash/Dashboard/test1/MainWindow.py", line 562, in can_read
    data = str(newMess)
NameError: global name 'newMess' is not defined
Aborted
libEGL warning: DRI2: failed to authenticate
Traceback (most recent call last):
  File "/home/pi/dash/Dashboard/test1/MainWindow.py", line 478, in increment
    self.fastRead()
  File "/home/pi/dash/Dashboard/test1/MainWindow.py", line 398, in fastRead
    line = self.can_read(0x300)
  File "/home/pi/dash/Dashboard/test1/MainWindow.py", line 562, in can_read
    data = str(newMess)
NameError: global name 'newMess' is not defined
Aborted
libEGL warning: DRI2: failed to authenticate
Traceback (most recent call last):
  File "/home/pi/dash/Dashboard/test1/MainWindow.py", line 478, in increment
    self.fastRead()
  File "/home/pi/dash/Dashboard/test1/MainWindow.py", line 398, in fastRead
    line = self.can_read(0x300)
  File "/home/pi/dash/Dashboard/test1/MainWindow.py", line 562, in can_read
    data = str(newMess)
NameError: global name 'newMess' is not defined
Aborted
libEGL warning: DRI2: failed to authenticate
Traceback (most recent call last):
  File "/home/pi/dash/Dashboard/test1/MainWindow.py", line 478, in increment
    self.fastRead()
  File "/home/pi/dash/Dashboard/test1/MainWindow.py", line 398, in fastRead
    line = self.can_read(0x300)
  File "/home/pi/dash/Dashboard/test1/MainWindow.py", line 562, in can_read
    data = str(newMess)
NameError: global name 'newMess' is not defined
Aborted
libEGL warning: DRI2: failed to authenticate
Traceback (most recent call last):
  File "/home/pi/dash/Dashboard/test1/MainWindow.py", line 478, in increment
    self.fastRead()
  File "/home/pi/dash/Dashboard/test1/MainWindow.py", line 398, in fastRead
    line = self.can_read(0x300)
  File "/home/pi/dash/Dashboard/test1/MainWindow.py", line 562, in can_read
    data = str(newMess)
NameError: global name 'newMess' is not defined
Aborted
QXcbConnection: Could not connect to display 
Aborted
libEGL warning: DRI2: failed to authenticate
Traceback (most recent call last):
  File "main.py", line 9, in <module>
    ex = MainWindow()
  File "/home/pi/dash/Dashboard/test1/MainWindow.py", line 307, in __init__
    self.bus = can.interface.Bus(bustype='socketcan', channel='can0', bitrate=500000)
  File "/home/pi/.local/lib/python2.7/site-packages/can/interface.py", line 87, in __new__
    return cls(channel, **kwargs)
  File "/home/pi/.local/lib/python2.7/site-packages/can/interfaces/socketcan/socketcan_ctypes.py", line 62, in __init__
    error = bindSocket(self.socket, channel)
  File "/home/pi/.local/lib/python2.7/site-packages/can/interfaces/socketcan/socketcan_ctypes.py", line 276, in bindSocket
    raise can.CanError(m)
can.CanError: Failure while getting "can0" interface index.
QXcbConnection: Could not connect to display 
Aborted
libEGL warning: DRI2: failed to authenticate
Traceback (most recent call last):
  File "/home/pi/dash/Dashboard/test1/MainWindow.py", line 478, in increment
    self.fastRead()
  File "/home/pi/dash/Dashboard/test1/MainWindow.py", line 398, in fastRead
    line = self.can_read(0x300)
  File "/home/pi/dash/Dashboard/test1/MainWindow.py", line 562, in can_read
    data = str(newMess)
NameError: global name 'newMess' is not defined
Aborted
libEGL warning: DRI2: failed to authenticate
Traceback (most recent call last):
  File "/home/pi/dash/Dashboard/test1/MainWindow.py", line 478, in increment
    self.fastRead()
  File "/home/pi/dash/Dashboard/test1/MainWindow.py", line 398, in fastRead
    line = self.can_read(0x300)
  File "/home/pi/dash/Dashboard/test1/MainWindow.py", line 562, in can_read
    data = str(newMess)
NameError: global name 'newMess' is not defined
Aborted
libEGL warning: DRI2: failed to authenticate
Traceback (most recent call last):
  File "/home/pi/dash/Dashboard/test1/MainWindow.py", line 478, in increment
    self.fastRead()
  File "/home/pi/dash/Dashboard/test1/MainWindow.py", line 398, in fastRead
    line = self.can_read(0x300)
  File "/home/pi/dash/Dashboard/test1/MainWindow.py", line 562, in can_read
    data = str(newMess)
NameError: global name 'newMess' is not defined
Aborted
libEGL warning: DRI2: failed to authenticate
Traceback (most recent call last):
  File "/home/pi/dash/Dashboard/test1/MainWindow.py", line 478, in increment
    self.fastRead()
  File "/home/pi/dash/Dashboard/test1/MainWindow.py", line 398, in fastRead
    line = self.can_read(0x300)
  File "/home/pi/dash/Dashboard/test1/MainWindow.py", line 562, in can_read
    data = str(newMess)
NameError: global name 'newMess' is not defined
Aborted
libEGL warning: DRI2: failed to authenticate
Traceback (most recent call last):
  File "/home/pi/dash/Dashboard/test1/MainWindow.py", line 478, in increment
    self.fastRead()
  File "/home/pi/dash/Dashboard/test1/MainWindow.py", line 398, in fastRead
    line = self.can_read(0x300)
  File "/home/pi/dash/Dashboard/test1/MainWindow.py", line 562, in can_read
    data = str(newMess)
NameError: global name 'newMess' is not defined
Aborted
libEGL warning: DRI2: failed to authenticate
Traceback (most recent call last):
  File "/home/pi/dash/Dashboard/test1/MainWindow.py", line 478, in increment
    self.fastRead()
  File "/home/pi/dash/Dashboard/test1/MainWindow.py", line 398, in fastRead
    line = self.can_read(0x300)
  File "/home/pi/dash/Dashboard/test1/MainWindow.py", line 562, in can_read
    data = str(newMess)
NameError: global name 'newMess' is not defined
Aborted
QXcbConnection: Could not connect to display 
Aborted
libEGL warning: DRI2: failed to authenticate
Traceback (most recent call last):
  File "main.py", line 9, in <module>
    ex = MainWindow()
  File "/home/pi/dash/Dashboard/test1/MainWindow.py", line 307, in __init__
    self.bus = can.interface.Bus(bustype='socketcan', channel='can0', bitrate=500000)
  File "/home/pi/.local/lib/python2.7/site-packages/can/interface.py", line 87, in __new__
    return cls(channel, **kwargs)
  File "/home/pi/.local/lib/python2.7/site-packages/can/interfaces/socketcan/socketcan_ctypes.py", line 62, in __init__
    error = bindSocket(self.socket, channel)
  File "/home/pi/.local/lib/python2.7/site-packages/can/interfaces/socketcan/socketcan_ctypes.py", line 276, in bindSocket
    raise can.CanError(m)
can.CanError: Failure while getting "can0" interface index.
                                                                                                                                                                                                                                                                                                                                                                                                                                                                                                                                                                                                                                                                                                                                                                                                                                                                                                                                                                                                                                                                                                                                                                                                                                                          Exception in thread Thread-1:
Traceback (most recent call last):
  File "/usr/lib/python2.7/threading.py", line 801, in __bootstrap_inner
    self.run()
  File "/usr/lib/python2.7/threading.py", line 754, in run
    self.__target(*self.__args, **self.__kwargs)
  File "/home/pi/dash/Dashboard/test1/MainWindow.py", line 77, in can_rx_task
    message = bus.recv()
NameError: global name 'bus' is not defined

QXcbConnection: Could not connect to display 
Aborted
Exception in thread Thread-1:
Traceback (most recent call last):
  File "/usr/lib/python2.7/threading.py", line 801, in __bootstrap_inner
    self.run()
  File "/usr/lib/python2.7/threading.py", line 754, in run
    self.__target(*self.__args, **self.__kwargs)
  File "/home/pi/dash/Dashboard/test1/MainWindow.py", line 77, in can_rx_task
    message = bus.recv()
NameError: global name 'bus' is not defined

libEGL warning: DRI2: failed to authenticate
Traceback (most recent call last):
  File "main.py", line 9, in <module>
    ex = MainWindow()
  File "/home/pi/dash/Dashboard/test1/MainWindow.py", line 370, in __init__
    self.bus = can.interface.Bus(bustype='socketcan', channel='can0', bitrate=500000)
  File "/home/pi/.local/lib/python2.7/site-packages/can/interface.py", line 87, in __new__
    return cls(channel, **kwargs)
  File "/home/pi/.local/lib/python2.7/site-packages/can/interfaces/socketcan/socketcan_ctypes.py", line 62, in __init__
    error = bindSocket(self.socket, channel)
  File "/home/pi/.local/lib/python2.7/site-packages/can/interfaces/socketcan/socketcan_ctypes.py", line 276, in bindSocket
    raise can.CanError(m)
can.CanError: Failure while getting "can0" interface index.
Exception in thread Thread-1:
Traceback (most recent call last):
  File "/usr/lib/python2.7/threading.py", line 801, in __bootstrap_inner
    self.run()
  File "/usr/lib/python2.7/threading.py", line 754, in run
    self.__target(*self.__args, **self.__kwargs)
  File "/home/pi/dash/Dashboard/test1/MainWindow.py", line 77, in can_rx_task
    message = bus.recv()
NameError: global name 'bus' is not defined

QXcbConnection: Could not connect to display 
Aborted
Exception in thread Thread-1:
Traceback (most recent call last):
  File "/usr/lib/python2.7/threading.py", line 801, in __bootstrap_inner
    self.run()
  File "/usr/lib/python2.7/threading.py", line 754, in run
    self.__target(*self.__args, **self.__kwargs)
  File "/home/pi/dash/Dashboard/test1/MainWindow.py", line 77, in can_rx_task
    message = bus.recv()
NameError: global name 'bus' is not defined

libEGL warning: DRI2: failed to authenticate
Traceback (most recent call last):
  File "main.py", line 9, in <module>
    ex = MainWindow()
  File "/home/pi/dash/Dashboard/test1/MainWindow.py", line 370, in __init__
    self.bus = can.interface.Bus(bustype='socketcan', channel='can0', bitrate=500000)
  File "/home/pi/.local/lib/python2.7/site-packages/can/interface.py", line 87, in __new__
    return cls(channel, **kwargs)
  File "/home/pi/.local/lib/python2.7/site-packages/can/interfaces/socketcan/socketcan_ctypes.py", line 62, in __init__
    error = bindSocket(self.socket, channel)
  File "/home/pi/.local/lib/python2.7/site-packages/can/interfaces/socketcan/socketcan_ctypes.py", line 276, in bindSocket
    raise can.CanError(m)
can.CanError: Failure while getting "can0" interface index.
Exception in thread Thread-1:
Traceback (most recent call last):
  File "/usr/lib/python2.7/threading.py", line 801, in __bootstrap_inner
    self.run()
  File "/usr/lib/python2.7/threading.py", line 754, in run
    self.__target(*self.__args, **self.__kwargs)
  File "/home/pi/dash/Dashboard/test1/MainWindow.py", line 77, in can_rx_task
    message = bus.recv()
NameError: global name 'bus' is not defined

QXcbConnection: Could not connect to display 
Aborted
Exception in thread Thread-1:
Traceback (most recent call last):
  File "/usr/lib/python2.7/threading.py", line 801, in __bootstrap_inner
    self.run()
  File "/usr/lib/python2.7/threading.py", line 754, in run
    self.__target(*self.__args, **self.__kwargs)
  File "/home/pi/dash/Dashboard/test1/MainWindow.py", line 77, in can_rx_task
    message = bus.recv()
NameError: global name 'bus' is not defined

libEGL warning: DRI2: failed to authenticate
Traceback (most recent call last):
  File "/home/pi/dash/Dashboard/test1/MainWindow.py", line 541, in increment
    self.fastRead()
  File "/home/pi/dash/Dashboard/test1/MainWindow.py", line 461, in fastRead
    line = self.can_read(0x300)
  File "/home/pi/dash/Dashboard/test1/MainWindow.py", line 625, in can_read
    data = str(newMess)
NameError: global name 'newMess' is not defined
Aborted
Exception in thread Thread-1:
Traceback (most recent call last):
  File "/usr/lib/python2.7/threading.py", line 801, in __bootstrap_inner
    self.run()
  File "/usr/lib/python2.7/threading.py", line 754, in run
    self.__target(*self.__args, **self.__kwargs)
  File "/home/pi/dash/Dashboard/test1/MainWindow.py", line 77, in can_rx_task
    message = bus.recv()
NameError: global name 'bus' is not defined

libEGL warning: DRI2: failed to authenticate
Traceback (most recent call last):
  File "/home/pi/dash/Dashboard/test1/MainWindow.py", line 541, in increment
    self.fastRead()
  File "/home/pi/dash/Dashboard/test1/MainWindow.py", line 461, in fastRead
    line = self.can_read(0x300)
  File "/home/pi/dash/Dashboard/test1/MainWindow.py", line 625, in can_read
    data = str(newMess)
NameError: global name 'newMess' is not defined
Aborted
Exception in thread Thread-1:
Traceback (most recent call last):
  File "/usr/lib/python2.7/threading.py", line 801, in __bootstrap_inner
    self.run()
  File "/usr/lib/python2.7/threading.py", line 754, in run
    self.__target(*self.__args, **self.__kwargs)
  File "/home/pi/dash/Dashboard/test1/MainWindow.py", line 77, in can_rx_task
    message = bus.recv()
NameError: global name 'bus' is not defined

libEGL warning: DRI2: failed to authenticate
Traceback (most recent call last):
  File "/home/pi/dash/Dashboard/test1/MainWindow.py", line 541, in increment
    self.fastRead()
  File "/home/pi/dash/Dashboard/test1/MainWindow.py", line 461, in fastRead
    line = self.can_read(0x300)
  File "/home/pi/dash/Dashboard/test1/MainWindow.py", line 625, in can_read
    data = str(newMess)
NameError: global name 'newMess' is not defined
Aborted
Exception in thread Thread-1:
Traceback (most recent call last):
  File "/usr/lib/python2.7/threading.py", line 801, in __bootstrap_inner
    self.run()
  File "/usr/lib/python2.7/threading.py", line 754, in run
    self.__target(*self.__args, **self.__kwargs)
  File "/home/pi/dash/Dashboard/test1/MainWindow.py", line 77, in can_rx_task
    message = bus.recv()
NameError: global name 'bus' is not defined

libEGL warning: DRI2: failed to authenticate
Traceback (most recent call last):
  File "/home/pi/dash/Dashboard/test1/MainWindow.py", line 541, in increment
    self.fastRead()
  File "/home/pi/dash/Dashboard/test1/MainWindow.py", line 461, in fastRead
    line = self.can_read(0x300)
  File "/home/pi/dash/Dashboard/test1/MainWindow.py", line 625, in can_read
    data = str(newMess)
NameError: global name 'newMess' is not defined
Aborted
Exception in thread Thread-1:
Traceback (most recent call last):
  File "/usr/lib/python2.7/threading.py", line 801, in __bootstrap_inner
    self.run()
  File "/usr/lib/python2.7/threading.py", line 754, in run
    self.__target(*self.__args, **self.__kwargs)
  File "/home/pi/dash/Dashboard/test1/MainWindow.py", line 77, in can_rx_task
    message = bus.recv()
NameError: global name 'bus' is not defined

libEGL warning: DRI2: failed to authenticate
Traceback (most recent call last):
  File "/home/pi/dash/Dashboard/test1/MainWindow.py", line 541, in increment
    self.fastRead()
  File "/home/pi/dash/Dashboard/test1/MainWindow.py", line 461, in fastRead
    line = self.can_read(0x300)
  File "/home/pi/dash/Dashboard/test1/MainWindow.py", line 625, in can_read
    data = str(newMess)
NameError: global name 'newMess' is not defined
Aborted
Exception in thread Thread-1:
Traceback (most recent call last):
  File "/usr/lib/python2.7/threading.py", line 801, in __bootstrap_inner
    self.run()
  File "/usr/lib/python2.7/threading.py", line 754, in run
    self.__target(*self.__args, **self.__kwargs)
  File "/home/pi/dash/Dashboard/test1/MainWindow.py", line 77, in can_rx_task
    message = bus.recv()
NameError: global name 'bus' is not defined

libEGL warning: DRI2: failed to authenticate
Traceback (most recent call last):
  File "/home/pi/dash/Dashboard/test1/MainWindow.py", line 541, in increment
    self.fastRead()
  File "/home/pi/dash/Dashboard/test1/MainWindow.py", line 461, in fastRead
    line = self.can_read(0x300)
  File "/home/pi/dash/Dashboard/test1/MainWindow.py", line 625, in can_read
    data = str(newMess)
NameError: global name 'newMess' is not defined
Aborted
Exception in thread Thread-1:
Traceback (most recent call last):
  File "/usr/lib/python2.7/threading.py", line 801, in __bootstrap_inner
    self.run()
  File "/usr/lib/python2.7/threading.py", line 754, in run
    self.__target(*self.__args, **self.__kwargs)
  File "/home/pi/dash/Dashboard/test1/MainWindow.py", line 77, in can_rx_task
    message = bus.recv()
NameError: global name 'bus' is not defined

QXcbConnection: Could not connect to display 
Aborted
Exception in thread Thread-1:
Traceback (most recent call last):
  File "/usr/lib/python2.7/threading.py", line 801, in __bootstrap_inner
    self.run()
  File "/usr/lib/python2.7/threading.py", line 754, in run
    self.__target(*self.__args, **self.__kwargs)
  File "/home/pi/dash/Dashboard/test1/MainWindow.py", line 77, in can_rx_task
    message = bus.recv()
NameError: global name 'bus' is not defined

libEGL warning: DRI2: failed to authenticate
Traceback (most recent call last):
  File "main.py", line 9, in <module>
    ex = MainWindow()
  File "/home/pi/dash/Dashboard/test1/MainWindow.py", line 370, in __init__
    self.bus = can.interface.Bus(bustype='socketcan', channel='can0', bitrate=500000)
  File "/home/pi/.local/lib/python2.7/site-packages/can/interface.py", line 87, in __new__
    return cls(channel, **kwargs)
  File "/home/pi/.local/lib/python2.7/site-packages/can/interfaces/socketcan/socketcan_ctypes.py", line 62, in __init__
    error = bindSocket(self.socket, channel)
  File "/home/pi/.local/lib/python2.7/site-packages/can/interfaces/socketcan/socketcan_ctypes.py", line 276, in bindSocket
    raise can.CanError(m)
can.CanError: Failure while getting "can0" interface index.
Traceback (most recent call last):
  File "main.py", line 4, in <module>
    from MainWindow import MainWindow
  File "/home/pi/dash/Dashboard/test1/MainWindow.py", line 90, in <module>
    bytesize=serial.SEVENBITS
  File "/home/pi/dash/Dashboard/test1/serial/serialutil.py", line 240, in __init__
    self.open()
  File "/home/pi/dash/Dashboard/test1/serial/serialposix.py", line 268, in open
    raise SerialException(msg.errno, "could not open port {}: {}".format(self._port, msg))
serial.serialutil.SerialException: [Errno 2] could not open port /dev/ttyACM0: [Errno 2] No such file or directory: '/dev/ttyACM0'
Exception in thread Thread-1:
Traceback (most recent call last):
  File "/usr/lib/python2.7/threading.py", line 801, in __bootstrap_inner
    self.run()
  File "/usr/lib/python2.7/threading.py", line 754, in run
    self.__target(*self.__args, **self.__kwargs)
  File "/home/pi/dash/Dashboard/test1/MainWindow.py", line 77, in can_rx_task
    message = bus.recv()
NameError: global name 'bus' is not defined

Traceback (most recent call last):
  File "main.py", line 4, in <module>
    from MainWindow import MainWindow
  File "/home/pi/dash/Dashboard/test1/MainWindow.py", line 90, in <module>
    bytesize=serial.SEVENBITS
  File "/home/pi/dash/Dashboard/test1/serial/serialutil.py", line 240, in __init__
    self.open()
  File "/home/pi/dash/Dashboard/test1/serial/serialposix.py", line 268, in open
    raise SerialException(msg.errno, "could not open port {}: {}".format(self._port, msg))
serial.serialutil.SerialException: [Errno 2] could not open port /dev/ttyACM0: [Errno 2] No such file or directory: '/dev/ttyACM0'
Exception in thread Thread-1:
Traceback (most recent call last):
  File "/usr/lib/python2.7/threading.py", line 801, in __bootstrap_inner
    self.run()
  File "/usr/lib/python2.7/threading.py", line 754, in run
    self.__target(*self.__args, **self.__kwargs)
  File "/home/pi/dash/Dashboard/test1/MainWindow.py", line 77, in can_rx_task
    message = bus.recv()
NameError: global name 'bus' is not defined

Traceback (most recent call last):
  File "main.py", line 4, in <module>
    from MainWindow import MainWindow
  File "/home/pi/dash/Dashboard/test1/MainWindow.py", line 32, in <module>
    xbus = can.interface.Bus(bustype='socketcan', channel='can0', bitrate=500000)
  File "/usr/local/lib/python2.7/dist-packages/can/interface.py", line 87, in __new__
    return cls(channel, **kwargs)
  File "/usr/local/lib/python2.7/dist-packages/can/interfaces/socketcan/socketcan_ctypes.py", line 62, in __init__
    error = bindSocket(self.socket, channel)
  File "/usr/local/lib/python2.7/dist-packages/can/interfaces/socketcan/socketcan_ctypes.py", line 276, in bindSocket
    raise can.CanError(m)
can.CanError: Failure while getting "can0" interface index.
Traceback (most recent call last):
  File "main.py", line 4, in <module>
    from MainWindow import MainWindow
  File "/home/pi/dash/Dashboard/test1/MainWindow.py", line 32, in <module>
    xbus = can.interface.Bus(bustype='socketcan', channel='can0', bitrate=500000)
  File "/home/pi/.local/lib/python2.7/site-packages/can/interface.py", line 87, in __new__
    return cls(channel, **kwargs)
  File "/home/pi/.local/lib/python2.7/site-packages/can/interfaces/socketcan/socketcan_ctypes.py", line 62, in __init__
    error = bindSocket(self.socket, channel)
  File "/home/pi/.local/lib/python2.7/site-packages/can/interfaces/socketcan/socketcan_ctypes.py", line 276, in bindSocket
    raise can.CanError(m)
can.CanError: Failure while getting "can0" interface index.
Traceback (most recent call last):
  File "main.py", line 4, in <module>
    from MainWindow import MainWindow
  File "/home/pi/dash/Dashboard/test1/MainWindow.py", line 32, in <module>
    xbus = can.interface.Bus(bustype='socketcan', channel='can0', bitrate=500000)
  File "/home/pi/.local/lib/python2.7/site-packages/can/interface.py", line 87, in __new__
    return cls(channel, **kwargs)
  File "/home/pi/.lTraceback (most recent call last):
  File "main.py", line 4, in <module>
    from MainWindow import MainWindow
  File "/home/pi/dash/Dashboard/test1/MainWindow.py", line 91, in <module>
    bytesize=serial.SEVENBITS
  File "/home/pi/dash/Dashboard/test1/serial/serialutil.py", line 240, in __init__
    self.open()
  File "/home/pi/dash/Dashboard/test1/serial/serialposix.py", line 268, in open
    raise SerialException(msg.errno, "could not open port {}: {}".format(self._port, msg))
serial.serialutil.SerialException: [Errno 2] could not open port /dev/ttyACM0: [Errno 2] No such file or directory: '/dev/ttyACM0'
Exception in thread Thread-1:
Traceback (most recent call last):
  File "/usr/lib/python2.7/threading.py", line 801, in __bootstrap_inner
    self.run()
  File "/usr/lib/python2.7/threading.py", line 754, in run
    self.__target(*self.__args, **self.__kwargs)
  File "/home/pi/dash/Dashboard/test1/MainWindow.py", line 78, in can_rx_task
    message = bus.recv()
NameError: global name 'bus' is not defined

Traceback (most recent call last):
  File "main.py", line 4, in <module>
    from MainWindow import MainWindow
  File "/home/pi/dash/Dashboard/test1/MainWindow.py", line 91, in <module>
    bytesize=serial.SEVENBITS
  File "/home/pi/dash/Dashboard/test1/serial/serialutil.py", line 240, in __init__
    self.open()
  File "/home/pi/dash/Dashboard/test1/serial/serialposix.py", line 268, in open
Exception in thread Thread-1:
Traceback (most recent call last):
  File "/usr/lib/python2.7/threading.py", line 801, in __bootstrap_inner
    self.run()
  File "/usr/lib/python2.7/threading.py", line 754, in run
    self.__target(*self.__args, **self.__kwargs)
  File "/home/pi/dash/Dashboard/test1/MainWindow.py", line 78, in can_rx_task
    message = bus.recv()
NameError: global name 'bus' is not defined
    
raise SerialException(msg.errno, "could not open port {}: {}".format(self._port, msg))
serial.serialutil.SerialException: [Errno 2] could not open port /dev/ttyACM0: [Errno 2] No such file or directory: '/dev/ttyACM0'
Exception in thread Thread-1:
Traceback (most recent call last):
  File "/usr/lib/python2.7/threading.py", line 801, in __bootstrap_inner
    self.run()
  File "/usr/lib/python2.7/threading.py", line 754, in run
    self.__target(*self.__args, **self.__kwargs)
  File "/home/pi/dash/Dashboard/test1/MainWindow.py", line 78, in can_rx_task
    message = bus.recv()
NameError: global name 'bus' is not defined

QXcbConnection: Could not connect to display 
Aborted
Exception in thread Thread-1:
Traceback (most recent call last):
  File "/usr/lib/python2.7/threading.py", line 801, in __bootstrap_inner
    self.run()
  File "/usr/lib/python2.7/threading.py", line 754, in run
    self.__target(*self.__args, **self.__kwargs)
  File "/home/pi/dash/Dashboard/test1/MainWindow.py", line 78, in can_rx_task
    message = bus.recv()
NameError: global name 'bus' is not defined

libEGL warning: DRI2: failed to authenticate
Exception in thread Thread-1:
Traceback (most recent call last):
  File "/usr/lib/python2.7/threading.py", line 801, in __bootstrap_inner
    self.run()
  File "/usr/lib/python2.7/threading.py", line 754, in run
    self.__target(*self.__args, **self.__kwargs)
  File "/home/pi/dash/Dashboard/test1/MainWindow.py", line 75, in can_rx_task
    bus = can.interface.Bus(bustype='socketcan', channel='can0', bitrate=500000)
  File "/usr/local/lib/python2.7/dist-packages/can/interface.py", line 87, in __new__
    return cls(channel, **kwargs)
  File "/usr/local/lib/python2.7/dist-packages/can/interfaces/socketcan/socketcan_ctypes.py", line 62, in __init__
    error = bindSocket(self.socket, channel)
  File "/usr/local/lib/python2.7/dist-packages/can/interfaces/socketcan/socketcan_ctypes.py", line 276, in bindSocket
    raise can.CanError(m)
CanError: Failure while getting "can0" interface index.

QXcbConnection: Could not connect to display 
Aborted
Exception in thread Thread-1:
Traceback (most recent call last):
  File "/usr/lib/python2.7/threading.py", line 801, in __bootstrap_inner
    self.run()
  File "/usr/lib/python2.7/threading.py", line 754, in run
    self.__target(*self.__args, **self.__kwargs)
  File "/home/pi/dash/Dashboard/test1/MainWindow.py", line 75, in can_rx_task
    bus = can.interface.Bus(bustype='socketcan', channel='can0', bitrate=500000)
  File "/home/pi/.local/lib/python2.7/site-packages/can/interface.py", line 87, in __new__
    return cls(channel, **kwargs)
  File "/home/pi/.local/lib/python2.7/site-packages/can/interfaces/socketcan/socketcan_ctypes.py", line 62, in __init__
    error = bindSocket(self.socket, channel)
  File "/home/pi/.local/lib/python2.7/site-packages/can/interfaces/socketcan/socketcan_ctypes.py", line 276, in bindSocket
    raise can.CanError(m)
CanError: Failure while getting "can0" interface index.

libEGL warning: DRI2: failed to authenticate
